Workbook

Sheet Santunan
B1: Date | C1: 45596
B4: No | C4: Nama Anak | D4: Proposal Santunan | E4: Keterangan
B5: Alm Keluarga George Leonard Dale
C6: 1 anak perempuan, Kelas 1 SMA
C7: Pekerjaan Ibu : Bantu cuci setrika
B8: 1 | C8: Jessika | D8: 750000 | E8: Kelas 1 SMA
B9: Alm Keluarga Tuwo
C10: 2 anak
C11: Pekerjaan Ibu : Belum ada | E11: Rencana usaha snack
B12: 1 | C12: Salmaan (15 tahun) | D12: 700000 | E12: Sekolah di Pondok (menginap)
B13: 2 | C13: Kariimah (13 tahun) | D13: 250000
B14: Alm Keluarga Rachmat Sjah
C15: 2 anak
C16: Ayah dan Ibu sudah berpulang
B17: 1 | C17: Farhan Bintang Rahmat | D17: TBD | E17: Kuliah tingkat akhir
B18: 2 | C18: Fajar | D18: 750000 | E18: Kelas 2 SMA
C19: Total per Bulan | D19: =SUM(D6:D18) -> 2450000

Sheet Penerimaan
D2: Tanggal Update | E2: =Pengeluaran!E2 -> Date
D3: Saldo Akhir | E3: =Pengeluaran!E3
E6: Delta per Bulan | F6: =F8-F7 -> 1216667 | G6: =G8-G7 -> 1566667 | H6: =H8-H7 -> 766667 | I6: =I8-I7 -> 1916667 | J6: =J8-J7 -> 866667 | K6: =K8-K7 -> 966667 | L6: =L8-L7 -> 766667 | M6: =M8-M7 -> 1016667 | ... AC6: =AC8-AC7 -> 300000
D7: Subtotal | E7: Pengeluaran | F7: =Pengeluaran!F7 -> 2450000 | G7: =Pengeluaran!G7 -> 2450000 | H7: 2450000 | I7: 2450000 | J7: 2450000 | K7: 2450000 | L7: 2450000 | M7: 2450000 | N7: 2450000 | O7: 2450000 | P7: 2450000 | Q7: 2450000 | R7: 2450000 | S7: 2450000 | T7: 2450000 | U7: 2450000 | V7: 0 | W7: 0 | X7: 0 | Y7: 0 | Z7: 0 | AA7: 0 | AB7: 0 | AC7: 0
D8: Subtotal | E8: Penerimaan | F8: =SUBTOTAL(9,F10:F99) -> 3666667 | G8: =SUBTOTAL(9,G10:G99) -> 4016667 | H8: =SUBTOTAL(9,H10:H99) -> 3216667 | I8: =SUBTOTAL(9,I10:I99) -> 4366667 | J8: =SUBTOTAL(9,J10:J99) -> 3316667 | K8: =SUBTOTAL(9,K10:K99) -> 3416667 | L8: =SUBTOTAL(9,L10:L99) -> 3216667 | M8: =SUBTOTAL(9,M10:M99) -> 3466667 | ... AC8: =SUBTOTAL(9,AC10:AC99) -> 300000
B9: No | C9: Kode Donatur | D9: Komitmen per Bulan | E9: Rencana Transfer | F9: 45597 | G9: 45627 | H9: 45658 | I9: 45689 | J9: 45717 | K9: 45748 | L9: 45778 | M9: 45809 | N9: 45839 | O9: 45870 | P9: 45901 | Q9: 45931 | R9: 45962 | S9: 45992 | T9: 46023 | U9: 46054 | V9: 46082 | W9: 46113 | X9: 46143 | Y9: 46174 | Z9: 46204 | AA9: 46235 | AB9: 46266 | AC9: 46296
B10: 1 | C10: DIODA-99 | E10: Insidental | F10: 100000 | G10: 600000 | H10: 100000 | I10: 100000 | K10: 100000 | L10: 400000 | M10: 100000 | N10: 100000 | O10: 100000 | P10: 100000 | Q10: 100000 | S10: 100000 | T10: 100000 | U10: 100000 | V10: 600000
B11: 2 | C11: DIODA-001X
B12: 3 | C12: DIODA-0028
B13: 4 | C13: DIODA-0036 | G13: 100000 | J13: 200000
B14: 5 | C14: DIODA-0044
B15: 6 | C15: DIODA-0052 | D15: 100000 | E15: per Bulan | F15: 100000 | G15: 200000 | I15: 400000 | J15: 200000 | L15: 500000 | M15: 200000 | N15: 200000 | Q15: 200000 | S15: 200000 | V15: 100000
B16: 7 | C16: DIODA-006Y
B17: 8 | C17: DIODA-0079 | H17: 500000 | K17: 500000
B18: 9 | C18: DIODA-0087
B19: 10 | C19: DIODA-0095
B20: 11 | C20: DIODA-0109 | E20: Insidental | F20: 200000 | M20: 300000
B21: 12 | C21: DIODA-0117
B22: 13 | C22: DIODA-0125
B23: 14 | C23: DIODA-0133 | K23: 200000 | T23: 200000
B24: 15 | C24: DIODA-0141
B25: 16 | C25: DIODA-015X
B26: 17 | C26: DIODA-0168 | D26: 100000 | E26: per Bulan | F26: 100000 | G26: 100000 | H26: 100000
B27: 18 | C27: DIODA-0176
B28: 19 | C28: DIODA-0184
B29: 20 | C29: DIODA-0192 | O29: 200000 | S29: 100000 | V29: 200000
B30: 21 | C30: DIODA-0206 | D30: 200000 | E30: per Bulan | F30: 200000 | G30: 200000 | H30: 200000 | I30: 200000 | J30: 200000 | K30: 200000 | L30: 200000 | M30: 200000 | N30: 200000 | O30: 200000 | Q30: 200000 | R30: 200000 | S30: 200000 | U30: 200000
B31: 22 | C31: DIODA-0222
B32: 23 | C32: DIODA-023Y | D32: 150000 | E32: per Bulan | F32: 200000 | G32: 200000 | H32: 200000 | I32: 250000 | J32: 200000 | K32: 200000 | L32: 200000 | M32: 200000 | N32: 200000 | O32: 200000 | Q32: 400000 | R32: 200000 | S32: 200000 | U32: 200000
B33: 24 | C33: DIODA-0257
B34: 25 | C34: DIODA-0265
B35: 26 | C35: DIODA-0273
B36: 27 | C36: DIODA-0281
B37: 28 | C37: DIODA-029X | G37: 500000 | M37: 350000 | O37: 150000 | Q37: 150000 | T37: 150000 | U37: 150000
B38: 29 | C38: DIODA-0303 | D38: 200000 | E38: per Semester | F38: 200000 | I38: 500000
B39: 30 | C39: DIODA-0311
B40: 31 | C40: DIODA-032X | F40: 300000 | G40: 300000 | I40: 300000 | N40: 300000 | P40: 600000 | Q40: 300000 | R40: 300000 | V40: 300000
B41: 32 | C41: DIODA-0346 | H41: 100000 | M41: 100000
B42: 33 | C42: DIODA-0354
B43: 34 | C43: DIODA-0362
...

Sheet Pengeluaran
D2: Tanggal Update | E2: Date
D3: Saldo Akhir
D5: Saldo | E5: Setelah | F5: =F6-F7 -> -2450000 | G5: =G6-G7 -> -2450000 | H5: =H6-H7 -> -2450000 | I5: =I6-I7 -> 0 | J5: =J6-J7 -> 0 | K5: =K6-K7 -> 0 | L5: =L6-L7 -> 0 | M5: =M6-M7 -> 0 | ... S5: =S6-S7 -> 0
D6: Saldo | E6: Sebelum
D7: Subtotal | E7: Pengeluaran | F7: =SUBTOTAL(9,F9:F13) -> 2450000 | G7: =SUBTOTAL(9,G9:G13) -> 2450000 | H7: =SUBTOTAL(9,H9:H13) -> 2450000 | I7: =SUBTOTAL(9,I9:I13) -> 0 | J7: =SUBTOTAL(9,J9:J13) -> 0 | K7: =SUBTOTAL(9,K9:K13) -> 0 | L7: =SUBTOTAL(9,L9:L13) -> 0 | M7: =SUBTOTAL(9,M9:M13) -> 0 | ... S7: =SUBTOTAL(9,S9:S13) -> 0
B8: No | C8: Keluarga Penerima | D8: Santunan per Keluarga | F8: 45597 | G8: 45627 | H8: 45658 | I8: 45689 | J8: 45717 | K8: 45748 | L8: 45778 | M8: 45809 | N8: 45839 | O8: 45870 | P8: 45901 | Q8: 45931 | R8: 45962 | S8: 45992
B9: 1 | C9: Keluarga George Bank Mandiri Acc: 1290005675406 a/n Siti Muthiah | D9: =SUM(Santunan!D6:D8) -> 750000 | E9: per Bulan | F9: 750000 | G9: 750000 | H9: 750000
B10: 2 | C10: Keluarga Tuwo Bank Mandiri Acc: 1490016437198 a/n Sri Astuti | D10: =SUM(Santunan!D10:D13) -> 950000 | E10: per Bulan | F10: 950000 | G10: 950000 | H10: 950000
B11: 3 | C11: Keluarga Rachmat Bank BCA Acc: 5725255281 a/n Farhan Bintang Rachmat | D11: =SUM(Santunan!D15:D18) -> 750000 | E11: per Bulan | F11: 750000 | G11: 750000 | H11: 750000
B16: No | C16: Tanggal | D16: Log Transfer (Special Case - Non Regular Transfer)
B17: 1
B18: 2
B19: 3
B20: 4
B21: 5

Sheet Bukti_Transfer
B3: Bulan | C3: 45658 | N3: Bulan | O3: 45597
B4: Tanggal | N4: Tanggal
B5: Alm Keluarga George | E5: Alm Keluarga Tuwo | H5: Alm Keluarga Rachmat Sjah | N5: Alm Keluarga George | Q5: Alm Keluarga Tuwo | T5: Alm Keluarga Rachmat Sjah
B16: Bulan | C16: =EOMONTH(C3,0)+1 -> 45689 | N16: Bulan | O16: =EOMONTH(O3,0)+1 -> 45627
B17: Tanggal | N17: Tanggal
B18: Alm Keluarga George | E18: Alm Keluarga Tuwo | H18: Alm Keluarga Rachmat Sjah | N18: Alm Keluarga George | Q18: Alm Keluarga Tuwo | T18: Alm Keluarga Rachmat Sjah
B29: Bulan | C29: =EOMONTH(C16,0)+1 -> 45717
B30: Tanggal
B31: Alm Keluarga George | E31: Alm Keluarga Tuwo | H31: Alm Keluarga Rachmat Sjah
B42: Bulan | C42: =EOMONTH(C29,0)+1 -> 45748
B43: Tanggal
B44: Alm Keluarga George | E44: Alm Keluarga Tuwo | H44: Alm Keluarga Rachmat Sjah
B55: Bulan | C55: =EOMONTH(C42,0)+1 -> 45778
B56: Tanggal
B57: Alm Keluarga George | E57: Alm Keluarga Tuwo | H57: Alm Keluarga Rachmat Sjah
B68: Bulan | C68: =EOMONTH(C55,0)+1 -> 45809
B69: Tanggal
B70: Alm Keluarga George | E70: Alm Keluarga Tuwo | H70: Alm Keluarga Rachmat Sjah
B81: Bulan | C81: =EOMONTH(C68,0)+1 -> 45839
B82: Tanggal
B83: Alm Keluarga George | E83: Alm Keluarga Tuwo | H83: Alm Keluarga Rachmat Sjah
B94: Bulan | C94: =EOMONTH(C81,0)+1 -> 45870
B95: Tanggal
B96: Alm Keluarga George | E96: Alm Keluarga Tuwo | H96: Alm Keluarga Rachmat Sjah
B107: Bulan | C107: =EOMONTH(C94,0)+1 -> 45901
B108: Tanggal
B109: Alm Keluarga George | E109: Alm Keluarga Tuwo | H109: Alm Keluarga Rachmat Sjah
B120: Bulan | C120: =EOMONTH(C107,0)+1 -> 45931
B121: Tanggal
B122: Alm Keluarga George | E122: Alm Keluarga Tuwo | H122: Alm Keluarga Rachmat Sjah
B133: Bulan | C133: =EOMONTH(C120,0)+1 -> 45962
B134: Tanggal
B135: Alm Keluarga George | E135: Alm Keluarga Tuwo | H135: Alm Keluarga Rachmat Sjah
B146: Bulan | C146: =EOMONTH(C133,0)+1 -> 45992
B147: Tanggal
B148: Alm Keluarga George | E148: Alm Keluarga Tuwo | H148: Alm Keluarga Rachmat Sjah

Sheet Donatur
B2: =SUBTOTAL(3,B5:B94) -> 90 | C2: =SUBTOTAL(3,C5:C94) -> 90
B3: NPM | C3: Nama | D3: Kode Donatur
B4: No Transfer Info | C4: Hamba ALLAH | D4: DIODA-99
B5: 049903001X | C5: A. Ademulia Djufri | D5: =CONCATENATE("DIODA-",RIGHT(B5,4)) -> DIODA-001X
B6: 0499030028 | C6: Achmad Nuriman | D6: =CONCATENATE("DIODA-",RIGHT(B6,4)) -> DIODA-0028
B7: 0499030036 | C7: Adhitya Pratama | D7: =CONCATENATE("DIODA-",RIGHT(B7,4)) -> DIODA-0036
B8: 0499030044 | C8: Adhitya Ubaidillah | D8: =CONCATENATE("DIODA-",RIGHT(B8,4)) -> DIODA-0044
B9: 0499030052 | C9: Adi Munandir | D9: =CONCATENATE("DIODA-",RIGHT(B9,4)) -> DIODA-0052
B10: 049903006Y | C10: Adi Vithara Purba | D10: =CONCATENATE("DIODA-",RIGHT(B10,4)) -> DIODA-006Y
B11: 0499030079 | C11: Agam Y. Mufty | D11: =CONCATENATE("DIODA-",RIGHT(B11,4)) -> DIODA-0079
B12: 0499030087 | C12: Agung Sulistriawan | D12: =CONCATENATE("DIODA-",RIGHT(B12,4)) -> DIODA-0087
B13: 0499030095 | C13: Agus Novianto | D13: =CONCATENATE("DIODA-",RIGHT(B13,4)) -> DIODA-0095
B14: 0499030109 | C14: Akhmad Zacky | D14: =CONCATENATE("DIODA-",RIGHT(B14,4)) -> DIODA-0109
B15: 0499030117 | C15: Alferdin | D15: =CONCATENATE("DIODA-",RIGHT(B15,4)) -> DIODA-0117
B16: 0499030125 | C16: Ali Zifan | D16: =CONCATENATE("DIODA-",RIGHT(B16,4)) -> DIODA-0125
... B94: 0499037138 | C94: Tuwo | D94: =CONCATENATE("DIODA-",RIGHT(B94,4)) -> DIODA-7138

Sheet Survey
B3: Survey E99 Berbagi
A4: 1 | B4: Mohon info nama dan nomor handphone aktif untuk pemberitahuan.
B5: Nama :
B6: No HP :
A7: 2 | B7: Apakah rekan E99 bersedia menjadi Donatur tetap E99 Berbagi? E99 Berbagi adalah program E99 FTUI yang bersifat sukarela untuk memberikan santunan pendidikan secara bulanan/reguler kepada Keluarga/Anak dari rekan E99 yang sudah berpulang.
B8: a. BERSEDIA, transfer per BULAN
B9: b. BERSEDIA, transfer per TRIWULAN (3 bulan)
B10: c. BERSEDIA, transfer per SEMESTER (6 bulan)
B11: d. BERSEDIA, transfer per TAHUN (12 bulan)
B12: e. BERSEDIA, transfer INSIDENTAL (tidak tetap)
B13: f. TIDAK BERSEDIA
A14: 3 | B14: Transfer ke Keluarga Alm Rekan E99 akan dilakukan per bulan, dan laporan bulanan akan diberikan per bulan di group E99. Reminder kepada Donatur akan disampaikan secara pribadi ke nomor HP yang diberitahukan. Donasi ini bersifat sukarela, donasi dapat diubah atau dihentikan dengan pemberitahuan secara pribadi ke Admin E99 Berbagi Ma'ruf Pattimura dan Fajar Muttaqin. Apakah ada saran lain untuk E99 Berbagi ?
B15: Free Text

Sheet Laporan
A1: Laporan E99 Berbagi November 2024 | D1: Laporan E99 Berbagi Desember 2024 | G1: Laporan E99 Berbagi Januari 2025 | J1: Laporan E99 Berbagi Februari 2025
A3: DIODA-99 | B3: 100000 | D3: DIODA-99 | E3: 600000 | G3: DIODA-99 | H3: 100000 | J3: DIODA-99 | K3: 100000
A4: DIODA-0052 | B4: 100000 | D4: DIODA-0036 | E4: 100000 | G4: DIODA-0079 | H4: 500000 | J4: DIODA-0052 | K4: 400000
A5: DIODA-0109 | B5: 200000 | D5: DIODA-0052 | E5: 200000 | G5: DIODA-0168 | H5: 100000 | J5: DIODA-0206 | K5: 200000
A6: DIODA-0168 | B6: 100000 | D6: DIODA-0168 | E6: 100000 | G6: DIODA-0206 | H6: 200000 | J6: DIODA-023Y | K6: 250000
A7: DIODA-0206 | B7: 200000 | D7: DIODA-0206 | E7: 200000 | G7: DIODA-023Y | H7: 200000 | J7: DIODA-0303 | K7: 500000
A8: DIODA-023Y | B8: 200000 | D8: DIODA-023Y | E8: 200000 | G8: DIODA-0346 | H8: 100000 | J8: DIODA-032X | K8: 300000
A9: DIODA-0303 | B9: 200000 | D9: DIODA-029X | E9: 500000 | G9: DIODA-0443 | H9: 200000 | J9: DIODA-0443 | K9: 200000
A10: DIODA-032X | B10: 300000 | D10: DIODA-032X | E10: 300000 | G10: DIODA-0516 | H10: 200000 | J10: DIODA-0516 | K10: 200000
A11: DIODA-0516 | B11: 200000 | D11: DIODA-0516 | E11: 200000 | G11: DIODA-0532 | H11: 300000 | J11: DIODA-0532 | K11: 300000
A12: DIODA-0532 | B12: 300000 | D12: DIODA-0532 | E12: 300000 | G12: DIODA-080X | H12: 300000 | J12: DIODA-0567 | K12: 100000
A13: DIODA-0567 | B13: 100000 | D13: DIODA-0605 | E13: 300000 | G13: DIODA-7057 | H13: 150000 | J13: DIODA-7057 | K13: 150000
A14: DIODA-0605 | B14: 300000 | D14: DIODA-7057 | E14: 150000 | G14: DIODA-709X | H14: 666667 | J14: DIODA-7065 | K14: 1000000
A15: DIODA-0621 | B15: 300000 | D15: DIODA-709X | E15: 666667 | G15: DIODA-7103 | H15: 200000 | J15: DIODA-709X | K15: 666667
A16: DIODA-703Y | B16: 250000 | D16: DIODA-7103 | E16: 200000 | G16: Pemasukan | H16: =SUM(H3:H15) -> 3216667 | J16: Pemasukan | K16: =SUM(K3:K15) -> 4366667
A17: DIODA-7057 | B17: 150000 | D17: Pemasukan | E17: =SUM(E3:E16) -> 4016667
A18: DIODA-709X | B18: 666667 | G18: Keluarga George | H18: 750000 | J18: Keluarga George | K18: 750000
A19: Pemasukan | B19: =SUM(B3:B18) -> 3666667 | D19: Keluarga George | E19: 750000 | G19: Keluarga Tuwo | H19: 950000 | J19: Keluarga Tuwo | K19: 950000
D20: Keluarga Tuwo | E20: 950000 | G20: Keluarga Rachmat | H20: 750000 | J20: Keluarga Rachmat | K20: 750000
A21: Keluarga George | B21: 750000 | D21: Keluarga Rachmat | E21: 750000 | G21: Pengeluaran | H21: =SUM(H18:H20) -> 2450000 | J21: Pengeluaran | K21: =SUM(K18:K20) -> 2450000
A22: Keluarga Tuwo | B22: 950000 | D22: Pengeluaran | E22: =SUM(E19:E21) -> 2450000
A23: Keluarga Rachmat | B23: 750000 | G23: Sisa Jan 2025 | H23: =H16-H21 -> 766667 | J23: Sisa Feb 2025 | K23: =K16-K21 -> 1916667
A24: Pengeluaran | B24: =SUM(B21:B23) -> 2450000 | D24: Sisa Des 2024 | E24: =E17-E22 -> 1566667 | G24: Saldo Sebelumnya | H24: =E26 -> 3383334 | J24: Saldo Sebelumnya | K24: =H25 -> 4150001
D25: Saldo Sebelumnya | E25: 1816667 | G25: Kas Donasi | H25: =H23+H24 -> 4150001 | J25: Kas Donasi | K25: =K23+K24 -> 6066668
A26: Sisa Nov 2024 | B26: =B19-B24 -> 1216667 | D26: Kas Donasi | E26: =SUM(E24:E25) -> 3383334
A27: Saldo Reuni Perak | B27: 600000
A28: Kas Donasi | B28: =SUM(B26:B27) -> 1816667
A32: Laporan E99 Berbagi Hari Raya | D32: Laporan E99 Berbagi Maret 2025 | G32: Laporan E99 Berbagi April 2025 | J32: Laporan E99 Berbagi Mei 2025
A34: Kas Donasi Sebelum | B34: =K25 -> 6066668 | D34: DIODA-0036 | E34: 200000 | G34: DIODA-99 | H34: 100000 | J34: DIODA-99 | K34: 400000
A35: Keluarga George | B35: 750000 | D35: DIODA-0052 | E35: 200000 | G35: DIODA-0079 | H35: 500000 | J35: DIODA-0052 | K35: 500000
A36: Keluarga Tuwo | B36: 950000 | D36: DIODA-0206 | E36: 200000 | G36: DIODA-0133 | H36: 200000 | J36: DIODA-0206 | K36: 200000
A37: Keluarga Rachmat | B37: 750000 | D37: DIODA-023Y | E37: 200000 | G37: DIODA-0206 | H37: 200000 | J37: DIODA-023Y | K37: 200000
A38: Kas saat ini | B38: =B34-B35-B36-B37 -> 3616668 | D38: DIODA-0443 | E38: 200000 | G38: DIODA-023Y | H38: 200000 | J38: DIODA-0443 | K38: 200000
D39: DIODA-0451 | E39: 100000 | G39: DIODA-0443 | H39: 200000 | J39: DIODA-0451 | K39: 100000
D40: DIODA-0516 | E40: 200000 | G40: DIODA-0451 | H40: 100000 | J40: DIODA-0516 | K40: 200000
D41: DIODA-0532 | E41: 300000 | G41: DIODA-0516 | H41: 200000 | J41: DIODA-0532 | K41: 300000
D42: DIODA-0567 | E42: 100000 | G42: DIODA-0532 | H42: 300000 | J42: DIODA-0567 | K42: 100000
D43: DIODA-0699 | E43: 100000 | G43: DIODA-0567 | H43: 100000 | J43: DIODA-0729 | K43: 200000
D44: DIODA-0729 | E44: 200000 | G44: DIODA-0729 | H44: 200000 | J44: DIODA-7057 | K44: 150000
D45: DIODA-7057 | E45: 150000 | G45: DIODA-703Y | H45: 300000 | J45: DIODA-709X | K45: 666667
...
